<?xml version="1.0" encoding="UTF-8"?>
<testng-results skipped="0" failed="1" total="1" passed="0">
  <reporter-output>
  </reporter-output>
  <suite name="Default suite" duration-ms="76123" started-at="2018-06-26T19:01:43Z" finished-at="2018-06-26T19:02:59Z">
    <groups>
    </groups>
    <test name="Default test" duration-ms="76123" started-at="2018-06-26T19:01:43Z" finished-at="2018-06-26T19:02:59Z">
      <class name="com.ys.appSpringBoot.NewTest">
        <test-method status="PASS" signature="initTest()[pri:0, instance:com.ys.appSpringBoot.NewTest@6a472554]" name="initTest" is-config="true" duration-ms="34707" started-at="2018-06-27T03:01:43Z" finished-at="2018-06-27T03:02:17Z">
          <reporter-output>
          </reporter-output>
        </test-method> <!-- initTest -->
        <test-method status="FAIL" signature="f(java.util.HashMap)[pri:0, instance:com.ys.appSpringBoot.NewTest@6a472554]" name="f" duration-ms="40523" started-at="2018-06-27T03:02:18Z" data-provider="app" finished-at="2018-06-27T03:02:59Z">
          <params>
            <param index="0">
              <value>
                <![CDATA[{NO=1, Description=µÇÂ¼, Expect=µÇÂ½³É¹¦, TCNO=XXX³¡¾°, Parameter=username:18234837159,pwd:123123qq, Process=LoginProcess, Step=1}]]>
              </value>
            </param>
          </params>
          <exception class="java.lang.AssertionError">
            <message>
              <![CDATA[expected [true] but found [false]]]>
            </message>
            <full-stacktrace>
              <![CDATA[java.lang.AssertionError: expected [true] but found [false]
	at org.testng.Assert.fail(Assert.java:94)
	at org.testng.Assert.failNotEquals(Assert.java:494)
	at org.testng.Assert.assertTrue(Assert.java:42)
	at org.testng.Assert.assertTrue(Assert.java:52)
	at com.ys.appSpringBoot.NewTest.f(NewTest.java:70)
	at sun.reflect.NativeMethodAccessorImpl.invoke0(Native Method)
	at sun.reflect.NativeMethodAccessorImpl.invoke(NativeMethodAccessorImpl.java:62)
	at sun.reflect.DelegatingMethodAccessorImpl.invoke(DelegatingMethodAccessorImpl.java:43)
	at java.lang.reflect.Method.invoke(Method.java:483)
	at org.testng.internal.MethodInvocationHelper.invokeMethod(MethodInvocationHelper.java:84)
	at org.testng.internal.Invoker.invokeMethod(Invoker.java:714)
	at org.testng.internal.Invoker.invokeTestMethod(Invoker.java:901)
	at org.testng.internal.Invoker.invokeTestMethods(Invoker.java:1231)
	at org.testng.internal.TestMethodWorker.invokeTestMethods(TestMethodWorker.java:127)
	at org.testng.internal.TestMethodWorker.run(TestMethodWorker.java:111)
	at org.testng.TestRunner.privateRun(TestRunner.java:767)
	at org.testng.TestRunner.run(TestRunner.java:617)
	at org.testng.SuiteRunner.runTest(SuiteRunner.java:335)
	at org.testng.SuiteRunner.runSequentially(SuiteRunner.java:330)
	at org.testng.SuiteRunner.privateRun(SuiteRunner.java:291)
	at org.testng.SuiteRunner.run(SuiteRunner.java:240)
	at org.testng.SuiteRunnerWorker.runSuite(SuiteRunnerWorker.java:52)
	at org.testng.SuiteRunnerWorker.run(SuiteRunnerWorker.java:86)
	at org.testng.TestNG.runSuitesSequentially(TestNG.java:1224)
	at org.testng.TestNG.runSuitesLocally(TestNG.java:1149)
	at org.testng.TestNG.run(TestNG.java:1057)
	at org.testng.remote.RemoteTestNG.run(RemoteTestNG.java:111)
	at org.testng.remote.RemoteTestNG.initAndRun(RemoteTestNG.java:204)
	at org.testng.remote.RemoteTestNG.main(RemoteTestNG.java:175)
]]>
            </full-stacktrace>
          </exception> <!-- java.lang.AssertionError -->
          <reporter-output>
          </reporter-output>
        </test-method> <!-- f -->
        <test-method status="PASS" signature="clenTest()[pri:0, instance:com.ys.appSpringBoot.NewTest@6a472554]" name="clenTest" is-config="true" duration-ms="0" started-at="2018-06-27T03:02:59Z" finished-at="2018-06-27T03:02:59Z">
          <reporter-output>
          </reporter-output>
        </test-method> <!-- clenTest -->
      </class> <!-- com.ys.appSpringBoot.NewTest -->
    </test> <!-- Default test -->
  </suite> <!-- Default suite -->
</testng-results>
